Workbook

Sheet LAI
Q1: jdurand - 2022-05-16 14:34
A4: Rapport statistique sur la Loi sur l’accès à l’information
A6: Nom de l’institution: | K6: =IF(D6="", "Vous devez entrer un nom d'institution", "") -> Vous devez entrer un nom d'institution
A8: Période d'établissement de rapport : | F8: 45748 | H8: au | I8: 46112
A10: Section 1 – Demandes en vertu de la Loi sur l’accès à l’information (LAI)
A12: 1.1 Nombre de demandes
H13: Nombre de demandes
A14: Reçues pendant la période d'établissement de rapport | H14: 0
A15: En suspens à la fin de la période d'établissement de rapport précédente | H15: =G16+G17 -> 0
A16: • En suspens à la fin de la période d'établissement de rapport précédente | G16: 0
A17: • En suspens pour plus d'une période d'établissement de rapport | G17: 0
A18: Total | H18: =H14+H15 -> 0
A19: Fermées pendant la période d'établissement de rapport | H19: 0
A20: Reportées à la prochaine période d'établissement de rapport | H20: =SUM(G21:G22) -> 0
A21: • Reportées à la prochaine période d'établissement de rapport dans les délais prévus par la LAI | G21: 0 | K21: =IF(H20<>(H18-H19),"""Reportées à la prochaine période d'établissement de rapport"" doit être égal au ""Total"" moins ""Fermées pendant la période d'établissement de rapport""","")
A22: • Reportées à la prochaine période d'établissement de rapport au-delà des délais prévus par la LAI | G22: 0
A24: 1.2 Source des demandes
A26: Source | G26: Nombre de demandes
A27: Médias | G27: 0
A28: Secteur universitaire | G28: 0
A29: Secteur commercial (secteur privé) | G29: 0
A30: Organisation | G30: 0
A31: Public | G31: 0
A32: Refus de s'identifier | G32: 0
A33: Total | G33: =SUM(G27:J32) -> 0
A35: 1.3 Mode des demandes
A37: Mode | G37: Nombre des demandes
A38: En ligne | G38: 0
A39: Courriel | G39: 0
A40: Poste | G40: 0
A41: En personne | G41: 0
A42: Téléphone | G42: 0
A43: Télécopieur | G43: 0
A44: Total | G44: =SUM(G38:J43) -> 0
A46: Section 2 – Demandes informelles
A48: 2.1 Nombre de demandes informelles
H49: Nombre de demandes
A50: Reçues pendant la période d'établissement de rapport | H50: 0
A51: En suspens à la fin de la période d'établissement de rapport précédente | H51: =SUM(G52:G53) -> 0
A52: • En suspens à la fin de la période d'établissement de rapport précédente | G52: 0
...

Sheet LPRP
AA1: JDURAND - 2022-05-13 12:05
A4: Rapport statistique sur la Loi sur la protection des renseignements personnels
E6: Nom de l’institution: | O6: =IF(H6="", "Vous devez entrer un nom d'institution", "") -> Vous devez entrer un nom d'institution
E8: Période d'établissement de rapport : | H8: 45748 | K8: au | L8: 46112
A10: Section 1 – Demandes en vertu de la Loi sur la protection des renseignements personnels (LPRP)
A12: 1.1 Nombre de demandes reçues
H14: Nombre de demandes
A15: Reçues pendant la période d'établissement de rapport | H15: 0
A16: En suspens à la fin de la période d'établissement de rapport précédente | H16: =SUM(G17:G18) -> 0
A17: • En suspens à la fin de la période d'établissement de rapport précédente | G17: 0
A18: • En suspens pour plus d'une période d'établissement de rapport | G18: 0
A19: Total | H19: =SUM(H15:J16) -> 0
A20: Fermées pendant la période d'établissement de rapport | H20: 0
A21: Reportées à la prochaine période d'établissement de rapport | H21: =SUM(G22:G23) -> 0
A22: • Reportées à la prochaine période d'établissement de rapport dans les délais prévus par la LPRP | G22: 0 | K22: =IF(H21<>(H19-H20),"""Reportées à la prochaine période d'établissement de rapport"" doit être égal au ""Total"" moins ""Fermées pendant la période d'établissement de rapport""","")
A23: • Reportées à la prochaine période d'établissement de rapport au-delà des délais prévus par la LPRP | G23: 0
A25: 1.2 Mode des demandes
A27: Mode | G27: Nombre des demandes
A28: En ligne | G28: 0
A29: Courriel | G29: 0
A30: Poste | G30: 0
A31: En personne | G31: 0
A32: Téléphone | G32: 0
A33: Télécopieur | G33: 0
A34: Total | G34: =SUM(G28:J33) -> 0
A36: Section 2 – Demandes informelles
A38: 2.1 Nombre de demandes informelles
H39: Nombre de demandes
A40: Reçues pendant la période d'établissement de rapport | H40: 0
A41: En suspens à la fin de la période d'établissement de rapport précédente | H41: =SUM(G42:G43) -> 0
A42: • En suspens à la fin de la période d'établissement de rapport précédente | G42: 0
A43: • En suspens pour plus d'une période d'établissement de rapport | G43: 0
A44: Total | H44: =SUM(H40:J41) -> 0
A45: Fermées pendant la période d'établissement de rapport | H45: 0
A46: Reportées à la prochaine période d'établissement de rapport | H46: =H44-H45 -> 0
A48: 2.2 Délai de traitement pour les demandes informelles
A50: Délai de traitement
A51: 0 à 15 jours | B51: 16 à 30 jours | C51: 31 à 60 jours | D51: 61 à 120 jours | E51: 121 à 180 jours | F51: 181 à 365 jours | G51: Plus de 365 jours | H51: Total
A52: 0 | B52: 0 | C52: 0 | D52: 0 | E52: 0 | F52: 0 | G52: 0 | H52: =SUM(A52:G52) -> 0
A54: 2.3 Pages communiquées informellement
...

Sheet ATI_ForConsumption
A1: Inst | B1: =LAI!D6 -> 0
A2: Report | B2: 2021;2022
A3: Q1R1C1 | B3: =LAI!H14 -> 0 | C3: 1,1
A4: Q1R2C1 | B4: =LAI!H15 -> 0 | C4: 1,1
A5: Q1R3C1 | B5: =LAI!G16 -> 0 | C5: 1,1
A6: Q1R4C1 | B6: =LAI!G17 -> 0 | C6: 1,1
A7: Q1R5C1 | B7: =LAI!H18 -> 0 | C7: 1,1
A8: Q1R6C1 | B8: =LAI!H19 -> 0 | C8: 1,1
A9: Q1R7C1 | B9: =LAI!H20 -> 0 | C9: 1,1
A10: Q1R8C1 | B10: =LAI!G21 -> 0 | C10: 1,1
A11: Q1R9C1 | B11: =LAI!G22 -> 0 | C11: 1,1
A12: Q2R1C1 | B12: =LAI!G27 -> 0 | C12: 1,2
A13: Q2R2C1 | B13: =LAI!G28 -> 0 | C13: 1,2
A14: Q2R3C1 | B14: =LAI!G29 -> 0 | C14: 1,2
A15: Q2R4C1 | B15: =LAI!G30 -> 0 | C15: 1,2
A16: Q2R5C1 | B16: =LAI!G31 -> 0 | C16: 1,2
A17: Q2R6C1 | B17: =LAI!G32 -> 0 | C17: 1,2
A18: Q2R7C1 | B18: =LAI!G33 -> 0 | C18: 1,2
A19: Q3R1C1 | B19: =LAI!G38 -> 0 | C19: 1,3
A20: Q3R2C1 | B20: =LAI!G39 -> 0 | C20: 1,3
A21: Q3R3C1 | B21: =LAI!G40 -> 0 | C21: 1,3
A22: Q3R4C1 | B22: =LAI!G41 -> 0 | C22: 1,3
A23: Q3R5C1 | B23: =LAI!G42 -> 0 | C23: 1,3
A24: Q3R6C1 | B24: =LAI!G43 -> 0 | C24: 1,3
A25: Q3R7C1 | B25: =LAI!G44 -> 0 | C25: 1,3
A26: Q4R1C1 | B26: =LAI!H50 -> 0 | C26: 2,1
A27: Q4R2C1 | B27: =LAI!H51 -> 0 | C27: 2,1
A28: Q4R3C1 | B28: =LAI!G52 -> 0 | C28: 2,1
A29: Q4R4C1 | B29: =LAI!G53 -> 0 | C29: 2,1
A30: Q4R5C1 | B30: =LAI!H54 -> 0 | C30: 2,1
A31: Q4R6C1 | B31: =LAI!H55 -> 0 | C31: 2,1
A32: Q4R7C1 | B32: =LAI!H56 -> 0 | C32: 2,1
A33: Q5R1C1 | B33: =LAI!#REF! -> #REF! | C33: 2,2
A34: Q5R2C1 | B34: =LAI!#REF! -> #REF! | C34: 2,2
A35: Q5R3C1 | B35: =LAI!#REF! -> #REF! | C35: 2,2
A36: Q5R4C1 | B36: =LAI!#REF! -> #REF! | C36: 2,2
A37: Q5R5C1 | B37: =LAI!#REF! -> #REF! | C37: 2,2
A38: Q5R6C1 | B38: =LAI!#REF! -> #REF! | C38: 2,2
A39: Q5R7C1 | B39: =LAI!#REF! -> #REF! | C39: 2,2
A40: Q6R1C1 | B40: =LAI!A62 -> 0 | C40: 2,3
...

Sheet Privacy_ForConsumption
A1: Inst | B1: =LPRP!H6 -> 0
A2: Report | B2: 2021;2022
A3: Q1R1C1 | B3: =LPRP!H15 -> 0 | C3: 1,1
A4: Q1R2C1 | B4: =LPRP!H16 -> 0 | C4: 1,1
A5: Q1R3C1 | B5: =LPRP!G17 -> 0 | C5: 1,1
A6: Q1R4C1 | B6: =LPRP!G18 -> 0 | C6: 1,1
A7: Q1R5C1 | B7: =LPRP!H19 -> 0 | C7: 1,1
A8: Q1R6C1 | B8: =LPRP!H20 -> 0 | C8: 1,1
A9: Q1R7C1 | B9: =LPRP!H21 -> 0 | C9: 1,1
A10: Q1R8C1 | B10: =LPRP!G22 -> 0 | C10: 1,1
A11: Q1R9C1 | B11: =LPRP!G23 -> 0 | C11: 1,1
A12: Q2R1C1 | B12: =LPRP!G28 -> 0 | C12: 1,2
A13: Q2R2C1 | B13: =LPRP!G29 -> 0 | C13: 1,2
A14: Q2R3C1 | B14: =LPRP!G30 -> 0 | C14: 1,2
A15: Q2R4C1 | B15: =LPRP!G31 -> 0 | C15: 1,2
A16: Q2R5C1 | B16: =LPRP!G32 -> 0 | C16: 1,2
A17: Q2R6C1 | B17: =LPRP!G33 -> 0 | C17: 1,2
A18: Q2R7C1 | B18: =LPRP!G34 -> 0 | C18: 1,2
A19: Q3R1C1 | B19: =LPRP!H40 -> 0 | C19: 2,1
A20: Q3R2C1 | B20: =LPRP!H41 -> 0 | C20: 2,1
A21: Q3R3C1 | B21: =LPRP!G42 -> 0 | C21: 2,1
A22: Q3R4C1 | B22: =LPRP!G43 -> 0 | C22: 2,1
A23: Q3R5C1 | B23: =LPRP!H44 -> 0 | C23: 2,1
A24: Q3R6C1 | B24: =LPRP!H45 -> 0 | C24: 2,1
A25: Q3R7C1 | B25: =LPRP!H46 -> 0 | C25: 2,1
A26: Q4R1C1 | B26: =LPRP!#REF! -> #REF! | C26: 2,2
A27: Q4R2C1 | B27: =LPRP!#REF! -> #REF! | C27: 2,2
A28: Q4R3C1 | B28: =LPRP!#REF! -> #REF! | C28: 2,2
A29: Q4R4C1 | B29: =LPRP!#REF! -> #REF! | C29: 2,2
A30: Q4R5C1 | B30: =LPRP!#REF! -> #REF! | C30: 2,2
A31: Q4R6C1 | B31: =LPRP!#REF! -> #REF! | C31: 2,2
A32: Q4R7C1 | B32: =LPRP!#REF! -> #REF! | C32: 2,2
A33: Q5R1C1 | B33: =LPRP!A52 -> 0 | C33: 2,3
A34: Q5R1C2 | B34: =LPRP!B52 -> 0 | C34: 2,3
A35: Q5R1C3 | B35: =LPRP!C52 -> 0 | C35: 2,3
A36: Q5R1C4 | B36: =LPRP!D52 -> 0 | C36: 2,3
A37: Q5R1C5 | B37: =LPRP!E52 -> 0 | C37: 2,3
A38: Q5R1C6 | B38: =LPRP!F52 -> 0 | C38: 2,3
A39: Q5R1C7 | B39: =LPRP!G52 -> 0 | C39: 2,3
A40: Q6R1C1 | B40: =LPRP!A58 -> 0 | C40: 2,4
...
