Workbook

Sheet Supplemental Report 2025-26
A4: Supplemental Statistical Report on the Access to Information Act and the Privacy Act
A7: Name of institution: | K7: =IF(D7="","You must enter an institution's name","") -> You must enter an institution's name
A9: Reporting period: | D9: 45748 | G9: to | H9: 46112
A11: Section 1: Requests Carried Over and Active Complaints Under the Access to Information Act
A13: 1.1 Requests carried over to next reporting period, broken down by reporting period received
A15: Reporting Period Requests Carried Over Were Received | D15: Requests Carried Over that are Within Legislated Timelines as of March 31, 2026 | F15: Requests Carried Over that are Beyond Legislated Timelines as of March 31, 2026 | H15: Total
A17: Received in 2025-26 | D17: 0 | F17: 0 | H17: =SUM(D17:G18) -> 0
A19: Received in 2024-25 | D19: 0 | F19: 0 | H19: =SUM(D19:G20) -> 0
A21: Received in 2023-24 | D21: 0 | F21: 0 | H21: =SUM(D21:G22) -> 0
A23: Received in 2022-23 | D23: 0 | F23: 0 | H23: =SUM(D23:G24) -> 0
A25: Received in 2021-22 | D25: 0 | F25: 0 | H25: =SUM(D25:G26) -> 0
A27: Received in 2020-21 | D27: 0 | F27: 0 | H27: =SUM(D27:G28) -> 0
A29: Received in 2019-20 | D29: 0 | F29: 0 | H29: =SUM(D29:G30) -> 0
A31: Received in 2018-19 | D31: 0 | F31: 0 | H31: =SUM(D31:G32) -> 0
A33: Received in 2017-18 | D33: 0 | F33: 0 | H33: =SUM(D33:G34) -> 0
A35: Received in 2016-17 or earlier | D35: 0 | F35: 0 | H35: =SUM(D35:G36) -> 0
A37: Total | D37: =SUM(D17:E36) -> 0 | F37: =SUM(F17:G36) -> 0 | H37: =SUM(D37:G38) -> 0 | J37: Row 11, Col. 3 of Section 1.1 must equal Row 7, Col. 1 of Section 1.1 of the 2025-26 Statistical Report on the Access to Information Act
A40: 1.2 Active complaints with the Information Commissioner of Canada, broken down by reporting period received
A43: Reporting Period Active Complaints Were Received by Institution | D43: Number of Active Complaints
A45: Received in 2025-26 | D45: 0
A47: Received in 2024-25 | D47: 0
A49: Received in 2023-24 | D49: 0
A51: Received in 2022-23 | D51: 0
A53: Received in 2021-22 | D53: 0
A55: Received in 2020-21 | D55: 0
A57: Received in 2019-20 | D57: 0
A59: Received in 2018-19 | D59: 0
A61: Received in 2017-18 | D61: 0
A63: Received in 2016-17 or earlier | D63: 0
A65: Total | D65: =SUM(D45:E64) -> 0
A68: Section 2: Requests Carried Over and Active Complaints Under the Privacy Act
A70: 2.1 Requests carried over to next reporting period, broken down by reporting period received
A72: Reporting Period Requests Carried Over Were Received | D72: Requests Carried Over that are Within Legislated Timelines as of March 31, 2026 | F72: Requests Carried Over that are Beyond Legislated Timelines as of March 31, 2026 | H72: Total
A74: Received in 2025-26 | D74: 0 | F74: 0 | H74: =SUM(D74:G75) -> 0
A76: Received in 2024-25 | D76: 0 | F76: 0 | H76: =SUM(D76:G77) -> 0
A78: Received in 2023-24 | D78: 0 | F78: 0 | H78: =SUM(D78:G79) -> 0
A80: Received in 2022-23 | D80: 0 | F80: 0 | H80: =SUM(D80:G81) -> 0
A82: Received in 2021-22 | D82: 0 | F82: 0 | H82: =SUM(D82:G83) -> 0
A84: Received in 2020-21 | D84: 0 | F84: 0 | H84: =SUM(D84:G85) -> 0
A86: Received in 2019-20 | D86: 0 | F86: 0 | H86: =SUM(D86:G87) -> 0
...

Sheet Section 5
A1: Validation List
A2: Yes
A3: No

Sheet Section 5 - FR
A1: Validation List
A2: Oui
A3: Non

Sheet AIPRP
A4: Rapport statistique supplémentaire sur la Loi sur l'accès à l'information et la Loi sur la protection des renseignements personnels
A7: Nom de l'institution :
A9: Période d'établissement de rapport : | D9: 43922 | G9: to | H9: 44286
A11: Section 1 : Capacité de recevoir des demandes d’accès à l’information
A13: Indiquez le nombre de semaines pendant lesquelles votre institution a pu recevoir des demandes d'AIPRP par les différents canaux.
H16: Nombre de semaines
A17: En mesure de recevoir des demandes par la poste | H17: 0
A18: En mesure de recevoir des demandes par courriel | H18: 0
A19: En mesure de recevoir des demandes au moyen d’un service de demande numérique | H19: 0
A21: Section 2 : Capacité de traiter les dossiers
A23: 2.1 Indiquez le nombre de semaines pendant lesquelles votre institution a pu traiter des documents papier dans différents formats et niveaux de classification.
D26: Ne peut pas traiter | F26: Peut traiter en partie | H26: Peut traiter en totalité | J26: Total
A28: Documents papiers non classifiés | D28: 0 | F28: 0 | H28: 0 | J28: =SUM(D28:I29) -> 0
A30: Documents papiers Protégé B | D30: 0 | F30: 0 | H30: 0 | J30: =SUM(D30:I31) -> 0
A32: Documents papiers Secret et Très secret | D32: 0 | F32: 0 | H32: 0 | J32: =SUM(D32:I33) -> 0
A35: 2.2 Indiquez le nombre de semaines pendant lesquelles votre institution a pu traiter des documents électroniques dans différents formats et niveaux de classification.
D38: Ne peut pas traiter | F38: Peut traiter en partie | H38: Peut traiter en totalité | J38: Total
A40: Documents électroniques non classifiés | D40: 0 | F40: 0 | H40: 0 | J40: =SUM(D40:I41) -> 0
A42: Documents électroniques Protégé B | D42: 0 | F42: 0 | H42: 0 | J42: =SUM(D42:I43) -> 0
A44: Documents électroniques Secret et Très secret | D44: 0 | F44: 0 | H44: 0 | J44: =SUM(D44:I45) -> 0
F48: - 1 -

Sheet ATIP_ForConsumption
A1: Inst | B1: ='Supplemental Report 2025-26'!D7 -> 0
A2: Report | B2: 2023;2024
A3: Q1R1C1 | B3: ='Supplemental Report 2025-26'!D17 -> 0 | C3: 1.1
A4: Q1R1C2 | B4: ='Supplemental Report 2025-26'!F17 -> 0 | C4: 1.1
A5: Q1R2C1 | B5: ='Supplemental Report 2025-26'!D19 -> 0 | C5: 1.1
A6: Q1R2C2 | B6: ='Supplemental Report 2025-26'!F19 -> 0 | C6: 1.1
A7: Q1R3C1 | B7: ='Supplemental Report 2025-26'!D21 -> 0 | C7: 1.1
A8: Q1R3C2 | B8: ='Supplemental Report 2025-26'!F21 -> 0 | C8: 1.1
A9: Q1R4C1 | B9: ='Supplemental Report 2025-26'!D23 -> 0 | C9: 1.1
A10: Q1R4C2 | B10: ='Supplemental Report 2025-26'!F23 -> 0 | C10: 1.1
A11: Q1R5C1 | B11: ='Supplemental Report 2025-26'!D25 -> 0 | C11: 1.1
A12: Q1R5C2 | B12: ='Supplemental Report 2025-26'!F25 -> 0 | C12: 1.1
A13: Q1R6C1 | B13: ='Supplemental Report 2025-26'!D27 -> 0 | C13: 1.1
A14: Q1R6C2 | B14: ='Supplemental Report 2025-26'!F27 -> 0 | C14: 1.1
A15: Q1R7C1 | B15: ='Supplemental Report 2025-26'!D29 -> 0 | C15: 1.1
A16: Q1R7C2 | B16: ='Supplemental Report 2025-26'!F29 -> 0 | C16: 1.1
A17: Q1R8C1 | B17: ='Supplemental Report 2025-26'!D31 -> 0 | C17: 1.1
A18: Q1R8C2 | B18: ='Supplemental Report 2025-26'!F31 -> 0 | C18: 1.1
A19: Q1R9C1 | B19: ='Supplemental Report 2025-26'!D33 -> 0 | C19: 1.1
A20: Q1R9C2 | B20: ='Supplemental Report 2025-26'!F33 -> 0 | C20: 1.1
A21: Q1R10C1 | B21: ='Supplemental Report 2025-26'!D35 -> 0 | C21: 1.1
A22: Q1R10C2 | B22: ='Supplemental Report 2025-26'!F35 -> 0 | C22: 1.1
A23: Q2R1C1 | B23: ='Supplemental Report 2025-26'!D45 -> 0 | C23: 1.2
A24: Q2R2C1 | B24: ='Supplemental Report 2025-26'!D47 -> 0 | C24: 1.2
A25: Q2R3C1 | B25: ='Supplemental Report 2025-26'!D49 -> 0 | C25: 1.2
A26: Q2R4C1 | B26: ='Supplemental Report 2025-26'!D51 -> 0 | C26: 1.2
A27: Q2R5C1 | B27: ='Supplemental Report 2025-26'!D53 -> 0 | C27: 1.2
A28: Q2R6C1 | B28: ='Supplemental Report 2025-26'!D55 -> 0 | C28: 1.2
A29: Q2R7C1 | B29: ='Supplemental Report 2025-26'!D57 -> 0 | C29: 1.2
A30: Q2R8C1 | B30: ='Supplemental Report 2025-26'!D59 -> 0 | C30: 1.2
A31: Q2R9C1 | B31: ='Supplemental Report 2025-26'!D61 -> 0 | C31: 1.2
A32: Q2R10C1 | B32: ='Supplemental Report 2025-26'!D63 -> 0 | C32: 1.2
A33: Q3R1C1 | B33: ='Supplemental Report 2025-26'!D74 -> 0 | C33: 2.1
A34: Q3R1C2 | B34: ='Supplemental Report 2025-26'!F74 -> 0 | C34: 2.1
A35: Q3R2C1 | B35: ='Supplemental Report 2025-26'!D76 -> 0 | C35: 2.1
A36: Q3R2C2 | B36: ='Supplemental Report 2025-26'!F76 -> 0 | C36: 2.1
A37: Q3R3C1 | B37: ='Supplemental Report 2025-26'!D78 -> 0 | C37: 2.1
A38: Q3R3C2 | B38: ='Supplemental Report 2025-26'!F78 -> 0 | C38: 2.1
A39: Q3R4C1 | B39: ='Supplemental Report 2025-26'!D80 -> 0 | C39: 2.1
A40: Q3R4C2 | B40: ='Supplemental Report 2025-26'!F80 -> 0 | C40: 2.1
...
