Workbook

Sheet ATI
A4: Statistical Report on the Access to Information Act
A6: Name of institution: | D6: 122 | K6: =IF(D6="", "You must enter an Institution name", "")
A8: Reporting period: | D8: 45748 | G8: to | H8: 46112
A10: Section 1: Requests Under the Access to Information Act
A12: 1.1 Number of requests
H13: Number of Requests
A14: Received during reporting period | H14: 0
A15: Outstanding from previous reporting periods | H15: =SUM(G16:G17) -> 1212
A16: • Outstanding from previous reporting period | G16: 1212
A17: • Outstanding from more than one reporting period | G17: 0
A18: Total | H18: =SUM(H14:J15) -> 1212
A19: Closed during reporting period | H19: 0
A20: Carried over to next reporting period | H20: =G21+G22 -> 0 | K20: =IF(H20<>(H18-H19),"Section 1.1 - The ""Carried over to next reporting period"" must equal to the ""Total"" minus ""Closed during reporting period"" of Section 1.1","") -> Section 1.1 - The "Carried over to next reporting period" must equal to the "Total" minus "Closed during reporting period" of Section 1.1
A21: • Carried over within legislated timeline | G21: 0
A22: • Carried over beyond legislated timeline | G22: 0
A24: 1.2 Sources of requests
A26: Source | G26: Number of Requests
A27: Media | G27: 0
A28: Academia | G28: 0
A29: Business (private sector) | G29: 0
A30: Organization | G30: 0
A31: Public | G31: 0
A32: Decline to Identify | G32: 0
A33: Total | G33: =SUM(G27:J32) -> 0
A35: 1.3 Channels of requests
A37: Source | G37: Number of Requests
A38: Online | G38: 0
A39: E-mail | G39: 0
A40: Mail | G40: 0
A41: In person | G41: 0
A42: Phone | G42: 0
A43: Fax | G43: 0
A44: Total | G44: =SUM(G38:J43) -> 0
A46: Section 2: Informal Requests
A48: 2.1 Number of informal requests
H49: Number of Requests
A50: Received during reporting period | H50: 0
A51: Outstanding from previous reporting periods | H51: =SUM(G52:G53) -> 0
A52: • Outstanding from previous reporting period | G52: 0
A53: • Outstanding from more than one reporting period | G53: 0
...

Sheet Priv
A4: Statistical Report on the Privacy Act
E6: Name of institution: | O6: =IF(H6="", "You must enter an Institution name", "") -> You must enter an Institution name
E8: Reporting period: | H8: 45748 | K8: to | L8: 46112
A10: Section 1: Requests Under the Privacy Act
A12: 1.1 Number of requests received
H14: Number of Requests
A15: Received during reporting period | H15: 0
A16: Outstanding from previous reporting periods | H16: =SUM(G17:G18) -> 0
A17: • Outstanding from previous reporting period | G17: 0
A18: • Outstanding from more than one reporting period | G18: 0
A19: Total | H19: =SUM(H15:J16) -> 0
A20: Closed during reporting period | H20: 0
A21: Carried over to next reporting period | H21: =SUM(G22:G23) -> 0
A22: • Carried over within legislated timeline | G22: 0 | K22: =IF(H21<>(H19-H20),"Section 1.1 - The ""Carried over to next reporting period"" must be equal to the ""Total"" minus ""Closed during the reporting period""","")
A23: • Carried over beyond legislated timeline | G23: 0
A25: 1.2 Channels of requests
A27: Source | G27: Number of Requests
A28: Online | G28: 0
A29: E-mail | G29: 0
A30: Mail | G30: 0
A31: In person | G31: 0
A32: Phone | G32: 0
A33: Fax | G33: 0
A34: Total | G34: =SUM(G28:J33) -> 0
A36: Section 2: Informal requests
A38: 2.1 Number of informal requests
H39: Number of Requests
A40: Received during reporting period | H40: 0
A41: Outstanding from previous reporting periods | H41: =SUM(G42:G43) -> 0
A42: • Outstanding from previous reporting period | G42: 0
A43: • Outstanding from more than one reporting period | G43: 0
A44: Total | H44: =SUM(H40:J41) -> 0
A45: Closed during reporting period | H45: 0
A46: Carried over to next reporting period | H46: =H44-H45 -> 0
A48: 2.2 Completion time of informal requests
A50: Completion Time
A51: 0 to 15 Days | B51: 16 to 30 Days | C51: 31 to 60 Days | D51: 61 to 120 Days | E51: 121 to 180 Days | F51: 181 to 365 Days | G51: More Than 365 Days | H51: Total
A52: 0 | B52: 0 | C52: 0 | D52: 0 | E52: 0 | F52: 0 | G52: 0 | H52: =SUM(A52:G52) -> 0
A54: 2.3 Pages released informally
A56: Less Than 500 Pages Released | C56: 500-10000 Pages Released | E56: More Than 10000 Pages Released
...

Sheet ATI_ForConsumption
A1: Inst | B1: =ATI!D6 -> 122
A2: Report | B2: 2021;2022
A3: Q1R1C1 | B3: =ATI!H14 -> 0 | C3: 1,1
A4: Q1R2C1 | B4: =ATI!H15 -> 1212 | C4: 1,1
A5: Q1R3C1 | B5: =ATI!G16 -> 1212 | C5: 1,1
A6: Q1R4C1 | B6: =ATI!G17 -> 0 | C6: 1,1
A7: Q1R5C1 | B7: =ATI!H18 -> 1212 | C7: 1,1
A8: Q1R6C1 | B8: =ATI!H19 -> 0 | C8: 1,1
A9: Q1R7C1 | B9: =ATI!H20 -> 0 | C9: 1,1
A10: Q1R8C1 | B10: =ATI!G21 -> 0 | C10: 1,1
A11: Q1R9C1 | B11: =ATI!G22 -> 0 | C11: 1,1
A12: Q2R1C1 | B12: =ATI!G27 -> 0 | C12: 1,2
A13: Q2R2C1 | B13: =ATI!G28 -> 0 | C13: 1,2
A14: Q2R3C1 | B14: =ATI!G29 -> 0 | C14: 1,2
A15: Q2R4C1 | B15: =ATI!G30 -> 0 | C15: 1,2
A16: Q2R5C1 | B16: =ATI!G31 -> 0 | C16: 1,2
A17: Q2R6C1 | B17: =ATI!G32 -> 0 | C17: 1,2
A18: Q2R7C1 | B18: =ATI!G33 -> 0 | C18: 1,2
A19: Q3R1C1 | B19: =ATI!G38 -> 0 | C19: 1,3
A20: Q3R2C1 | B20: =ATI!G39 -> 0 | C20: 1,3
A21: Q3R3C1 | B21: =ATI!G40 -> 0 | C21: 1,3
A22: Q3R4C1 | B22: =ATI!G41 -> 0 | C22: 1,3
A23: Q3R5C1 | B23: =ATI!G42 -> 0 | C23: 1,3
A24: Q3R6C1 | B24: =ATI!G43 -> 0 | C24: 1,3
A25: Q3R7C1 | B25: =ATI!G44 -> 0 | C25: 1,3
A26: Q4R1C1 | B26: =ATI!H50 -> 0 | C26: 2,1
A27: Q4R2C1 | B27: =ATI!H51 -> 0 | C27: 2,1
A28: Q4R3C1 | B28: =ATI!G52 -> 0 | C28: 2,1
A29: Q4R4C1 | B29: =ATI!G53 -> 0 | C29: 2,1
A30: Q4R5C1 | B30: =ATI!H54 -> 0 | C30: 2,1
A31: Q4R6C1 | B31: =ATI!H55 -> 0 | C31: 2,1
A32: Q4R7C1 | B32: =ATI!H56 -> 0 | C32: 2,1
A33: Q5R1C1 | B33: =ATI!#REF! -> #ERROR! | C33: 2,2
A34: Q5R2C1 | B34: =ATI!#REF! -> #ERROR! | C34: 2,2
A35: Q5R3C1 | B35: =ATI!#REF! -> #ERROR! | C35: 2,2
A36: Q5R4C1 | B36: =ATI!#REF! -> #ERROR! | C36: 2,2
A37: Q5R5C1 | B37: =ATI!#REF! -> #ERROR! | C37: 2,2
A38: Q5R6C1 | B38: =ATI!#REF! -> #ERROR! | C38: 2,2
A39: Q5R7C1 | B39: =ATI!#REF! -> #ERROR! | C39: 2,2
A40: Q6R1C1 | B40: =ATI!A63 -> 0 | C40: 2,3
...

Sheet Privacy_ForConsumption
A1: Inst | B1: =Priv!H6
A2: Report | B2: 2021;2022
A3: Q1R1C1 | B3: =Priv!H15 -> 0 | C3: 1,1
A4: Q1R2C1 | B4: =Priv!H16 -> 0 | C4: 1,1
A5: Q1R3C1 | B5: =Priv!G17 -> 0 | C5: 1,1
A6: Q1R4C1 | B6: =Priv!G18 -> 0 | C6: 1,1
A7: Q1R5C1 | B7: =Priv!H19 -> 0 | C7: 1,1
A8: Q1R6C1 | B8: =Priv!H20 -> 0 | C8: 1,1
A9: Q1R7C1 | B9: =Priv!H21 -> 0 | C9: 1,1
A10: Q1R8C1 | B10: =Priv!G22 -> 0 | C10: 1,1
A11: Q1R9C1 | B11: =Priv!G23 -> 0 | C11: 1,1
A12: Q2R1C1 | B12: =Priv!G28 -> 0 | C12: 1,2
A13: Q2R2C1 | B13: =Priv!G29 -> 0 | C13: 1,2
A14: Q2R3C1 | B14: =Priv!G30 -> 0 | C14: 1,2
A15: Q2R4C1 | B15: =Priv!G31 -> 0 | C15: 1,2
A16: Q2R5C1 | B16: =Priv!G32 -> 0 | C16: 1,2
A17: Q2R6C1 | B17: =Priv!G33 -> 0 | C17: 1,2
A18: Q2R7C1 | B18: =Priv!G34 -> 0 | C18: 1,2
A19: Q3R1C1 | B19: =Priv!H40 -> 0 | C19: 2,1
A20: Q3R2C1 | B20: =Priv!H41 -> 0 | C20: 2,1
A21: Q3R3C1 | B21: =Priv!G42 -> 0 | C21: 2,1
A22: Q3R4C1 | B22: =Priv!G43 -> 0 | C22: 2,1
A23: Q3R5C1 | B23: =Priv!H44 -> 0 | C23: 2,1
A24: Q3R6C1 | B24: =Priv!H45 -> 0 | C24: 2,1
A25: Q3R7C1 | B25: =Priv!H46 -> 0 | C25: 2,1
A26: Q4R1C1 | B26: =Priv!#REF! -> #ERROR! | C26: 2,2
A27: Q4R2C1 | B27: =Priv!#REF! -> #ERROR! | C27: 2,2
A28: Q4R3C1 | B28: =Priv!#REF! -> #ERROR! | C28: 2,2
A29: Q4R4C1 | B29: =Priv!#REF! -> #ERROR! | C29: 2,2
A30: Q4R5C1 | B30: =Priv!#REF! -> #ERROR! | C30: 2,2
A31: Q4R6C1 | B31: =Priv!#REF! -> #ERROR! | C31: 2,2
A32: Q4R7C1 | B32: =Priv!#REF! -> #ERROR! | C32: 2,2
A33: Q5R1C1 | B33: =Priv!A52 -> 0 | C33: 2,3
A34: Q5R1C2 | B34: =Priv!B52 -> 0 | C34: 2,3
A35: Q5R1C3 | B35: =Priv!C52 -> 0 | C35: 2,3
A36: Q5R1C4 | B36: =Priv!D52 -> 0 | C36: 2,3
A37: Q5R1C5 | B37: =Priv!E52 -> 0 | C37: 2,3
A38: Q5R1C6 | B38: =Priv!F52 -> 0 | C38: 2,3
A39: Q5R1C7 | B39: =Priv!G52 -> 0 | C39: 2,3
A40: Q6R1C1 | B40: =Priv!A58 -> 0 | C40: 2,4
...
