Workbook

Sheet LAI
AA1: jdurand - 2022-05-16 14:34
A4: Rapport statistique sur la Loi sur l’accès à l’information
A6: Nom de l’institution: | D6: Défense nationale | K6: Vous devez entrer le nom d'une institution
A8: 45017 | F8: 45383 | H8: 45382 | I8: 45747
A10: Section 1 – Demandes en vertu de la Loi sur l’accès à l’information
A12: 1.1 Nombre de demandes
H13: Nombre de demandes
A14: Reçues pendant la période d'établissement de rapport | H14: 2347
A15: En suspens à la fin de la période d'établissement de rapport précédente | H15: =G16+G17
A16: • En suspens à la fin de la période d'établissement de rapport précédente | G16: 183
A17: • En suspens pour plus d'une période d'établissement de rapport | G17: 1594
A18: Total | H18: =H14+H15
A19: Fermées pendant la période d'établissement de rapport | H19: 2086
A20: Reportées à la prochaine période d'établissement de rapport | H20: =SUM(G21:G22) | M20: Section 1.1 - Le montant "Reportées à la prochaine période d'établissement de rapport" doit être égal au "Total" moins "Fermées pendant la période d'établissement de rapport".
A21: • Reportées à la prochaine période d'établissement de rapport dans les délais prévus par la Loi | G21: 186
A22: • Reportées à la prochaine période d'établissement de rapport au-delà des délais prévus par la Loi | G22: 1852
A24: 1.2 Source des demandes
A26: Source | G26: Nombre de demandes
A27: Médias | G27: 486
A28: Secteur universitaire | G28: 74
A29: Secteur commercial (secteur privé) | G29: 134
A30: Organisation | G30: 21
A31: Public | G31: 1536
A32: Refus de s'identifier | G32: 96 | M32: Section 1.2 - Le "Total" doit être égal au montant "Reçues pendant la période d'établissement de rapport" de la Section 1.1
A33: Total | G33: =SUM(G27:J32)
A35: 1.3 Mode des demandes
A37: Mode | G37: Nombre des demandes
A38: En ligne | G38: 2217
A39: Courriel | G39: 60
A40: Poste | G40: 70
A41: En personne | G41: 0
A42: Téléphone | G42: 0
A43: Télécopieur | G43: 0 | M43: Section 1.3 - Le "Total" doit être égal au montant "Reçues pendant la période d'établissement de rapport" de la Section 1.1
A44: Total | G44: =SUM(G38:J43)
A46: Section 2 – Demandes informelles
A48: 2.1 Nombre de demandes informelles
H49: Nombre de demandes
A50: Reçues pendant la période d'établissement de rapport | H50: 969
A51: En suspens à la fin de la période d'établissement de rapport précédente | H51: =SUM(G52:G53)
A52: • En suspens à la fin de la période d'établissement de rapport précédente | G52: 86
...

Sheet LPRP
AA1: JDURAND - 2022-05-13 12:05
A4: Rapport statistique sur la Loi sur la protection des renseignements personnels
E6: Nom de l’institution: | O6: Vous devez entrer un nom d'institution
E8: Période d'établissement de rapport : | H8: 45383 | K8: au | L8: 45747
A10: Section 1 – Demandes en vertu de la Loi sur la protection des renseignements personnels
A12: 1.1 Nombre de demandes reçues
H14: Nombre de demandes
A15: Reçues pendant la période d'établissement de rapport | H15: 0
A16: En suspens à la fin de la période d'établissement de rapport précédente | H16: =SUM(G17:G18)
A17: • En suspens à la fin de la période d'établissement de rapport précédente | G17: 0
A18: • En suspens pour plus d'une période d'établissement de rapport | G18: 0
A19: Total | H19: =SUM(H15:J16)
A20: Fermées pendant la période d'établissement de rapport | H20: 0
A21: Reportées à la prochaine période d'établissement de rapport | H21: =SUM(G22:G23) | K21: Section 1.1 - Le montant "Reportées à la prochaine période d'établissement de rapport" doit être égal au "Total" moins "Fermées pendant la période d'établissement de rapport".
A22: • Reportées à la prochaine période d'établissement de rapport dans les délais prévus par la Loi | G22: 0
A23: • Reportées à la prochaine période d'établissement de rapport au-delà des délais prévus par la Loi | G23: 0
A25: 1.2 Mode des demandes
A27: Mode | G27: Nombre des demandes
A28: En ligne | G28: 0
A29: Courriel | G29: 0
A30: Poste | G30: 0
A31: En personne | G31: 0
A32: Téléphone | G32: 0
A33: Télécopieur | G33: 0
A34: Total | G34: =SUM(G28:J33) | K34: Section 1.2 - Le "Total" doit être égal au montant de "Reçues pendant la période d'établissement de rapport" de la Section 1.1
A36: Section 2 – Demandes informelles
A40: 2.1 Nombre de demandes informelles
H41: Nombre de demandes
A42: Reçues pendant la période d'établissement de rapport | H42: 0 | K42: Section 2.1 - Le "Nombre de demandes" "Reçues pendant la période d'établissement de rapport" doit être égal au "Total" de la Section 2.2
A43: En suspens à la fin de la période d'établissement de rapport précédente | H43: =SUM(G44:G45)
A44: • En suspens à la fin de la période d'établissement de rapport précédente | G44: 0
A45: • En suspens pour plus d'une période d'établissement de rapport | G45: 0
A46: Total | H46: =SUM(H42:J43)
A47: Fermées pendant la période d'établissement de rapport | H47: 0
A48: Reportées à la prochaine période d'établissement de rapport | H48: =H46-H47
A50: 2.2 Mode des demandes informelles
A52: Mode | G52: Nombre des demandes
A53: En ligne | G53: 0
A54: Courriel | G54: 0
A55: Poste | G55: 0
...

Sheet ATI_ForConsumption
A1: Inst | B1: =LAI!D6
A2: Report | B2: 2021;2022
A3: Q1R1C1 | B3: =LAI!H14 | C3: 1,1
A4: Q1R2C1 | B4: =LAI!H15 | C4: 1,1
A5: Q1R3C1 | B5: =LAI!G16 | C5: 1,1
A6: Q1R4C1 | B6: =LAI!G17 | C6: 1,1
A7: Q1R5C1 | B7: =LAI!H18 | C7: 1,1
A8: Q1R6C1 | B8: =LAI!H19 | C8: 1,1
A9: Q1R7C1 | B9: =LAI!H20 | C9: 1,1
A10: Q1R8C1 | B10: =LAI!G21 | C10: 1,1
A11: Q1R9C1 | B11: =LAI!G22 | C11: 1,1
A12: Q2R1C1 | B12: =LAI!G27 | C12: 1,2
A13: Q2R2C1 | B13: =LAI!G28 | C13: 1,2
A14: Q2R3C1 | B14: =LAI!G29 | C14: 1,2
A15: Q2R4C1 | B15: =LAI!G30 | C15: 1,2
A16: Q2R5C1 | B16: =LAI!G31 | C16: 1,2
A17: Q2R6C1 | B17: =LAI!G32 | C17: 1,2
A18: Q2R7C1 | B18: =LAI!G33 | C18: 1,2
A19: Q3R1C1 | B19: =LAI!G38 | C19: 1,3
A20: Q3R2C1 | B20: =LAI!G39 | C20: 1,3
A21: Q3R3C1 | B21: =LAI!G40 | C21: 1,3
A22: Q3R4C1 | B22: =LAI!G41 | C22: 1,3
A23: Q3R5C1 | B23: =LAI!G42 | C23: 1,3
A24: Q3R6C1 | B24: =LAI!G43 | C24: 1,3
A25: Q3R7C1 | B25: =LAI!G44 | C25: 1,3
A26: Q4R1C1 | B26: =LAI!H50 | C26: 2,1
A27: Q4R2C1 | B27: =LAI!H51 | C27: 2,1
A28: Q4R3C1 | B28: =LAI!G52 | C28: 2,1
A29: Q4R4C1 | B29: =LAI!G53 | C29: 2,1
A30: Q4R5C1 | B30: =LAI!H54 | C30: 2,1
A31: Q4R6C1 | B31: =LAI!H55 | C31: 2,1
A32: Q4R7C1 | B32: =LAI!H56 | C32: 2,1
A33: Q5R1C1 | B33: =LAI!G61 | C33: 2,2
A34: Q5R2C1 | B34: =LAI!G62 | C34: 2,2
A35: Q5R3C1 | B35: =LAI!G63 | C35: 2,2
A36: Q5R4C1 | B36: =LAI!G64 | C36: 2,2
A37: Q5R5C1 | B37: =LAI!G65 | C37: 2,2
A38: Q5R6C1 | B38: =LAI!G66 | C38: 2,2
A39: Q5R7C1 | B39: =LAI!G67 | C39: 2,2
A40: Q6R1C1 | B40: =LAI!A73 | C40: 2,3
...

Sheet Privacy_ForConsumption
A1: Inst | B1: =LPRP!H6
A2: Report | B2: 2021;2022
A3: Q1R1C1 | B3: =LPRP!H15 | C3: 1,1
A4: Q1R2C1 | B4: =LPRP!H16 | C4: 1,1
A5: Q1R3C1 | B5: =LPRP!G17 | C5: 1,1
A6: Q1R4C1 | B6: =LPRP!G18 | C6: 1,1
A7: Q1R5C1 | B7: =LPRP!H19 | C7: 1,1
A8: Q1R6C1 | B8: =LPRP!H20 | C8: 1,1
A9: Q1R7C1 | B9: =LPRP!H21 | C9: 1,1
A10: Q1R8C1 | B10: =LPRP!G22 | C10: 1,1
A11: Q1R9C1 | B11: =LPRP!G23 | C11: 1,1
A12: Q2R1C1 | B12: =LPRP!G28 | C12: 1,2
A13: Q2R2C1 | B13: =LPRP!G29 | C13: 1,2
A14: Q2R3C1 | B14: =LPRP!G30 | C14: 1,2
A15: Q2R4C1 | B15: =LPRP!G31 | C15: 1,2
A16: Q2R5C1 | B16: =LPRP!G32 | C16: 1,2
A17: Q2R6C1 | B17: =LPRP!G33 | C17: 1,2
A18: Q2R7C1 | B18: =LPRP!G34 | C18: 1,2
A19: Q3R1C1 | B19: =LPRP!H42 | C19: 2,1
A20: Q3R2C1 | B20: =LPRP!H43 | C20: 2,1
A21: Q3R3C1 | B21: =LPRP!G44 | C21: 2,1
A22: Q3R4C1 | B22: =LPRP!G45 | C22: 2,1
A23: Q3R5C1 | B23: =LPRP!H46 | C23: 2,1
A24: Q3R6C1 | B24: =LPRP!H47 | C24: 2,1
A25: Q3R7C1 | B25: =LPRP!H48 | C25: 2,1
A26: Q4R1C1 | B26: =LPRP!G53 | C26: 2,2
A27: Q4R2C1 | B27: =LPRP!G54 | C27: 2,2
A28: Q4R3C1 | B28: =LPRP!G55 | C28: 2,2
A29: Q4R4C1 | B29: =LPRP!G56 | C29: 2,2
A30: Q4R5C1 | B30: =LPRP!G57 | C30: 2,2
A31: Q4R6C1 | B31: =LPRP!G58 | C31: 2,2
A32: Q4R7C1 | B32: =LPRP!G59 | C32: 2,2
A33: Q5R1C1 | B33: =LPRP!A65 | C33: 2,3
A34: Q5R1C2 | B34: =LPRP!B65 | C34: 2,3
A35: Q5R1C3 | B35: =LPRP!C65 | C35: 2,3
A36: Q5R1C4 | B36: =LPRP!D65 | C36: 2,3
A37: Q5R1C5 | B37: =LPRP!E65 | C37: 2,3
A38: Q5R1C6 | B38: =LPRP!F65 | C38: 2,3
A39: Q5R1C7 | B39: =LPRP!G65 | C39: 2,3
A40: Q6R1C1 | B40: =LPRP!A71 | C40: 2,4
...
