Workbook

Sheet ATI
AA1: JDURAND - 2022-05-13 15:03
A4: Statistical Report on the Access to Information Act
A6: Name of institution: | M6: You must enter an Institution name
A8: Reporting period: | D8: 45383 | G8: to | H8: 45747
A10: Section 1: Requests Under the Access to Information Act
A12: 1.1 Number of requests
H13: Number of Requests
A14: Received during reporting period | H14: 0 | M14: =IF(H14<0,"Section 1.1 - Number of received requests cannot be negative","")
A15: Outstanding from previous reporting periods | H15: =SUM(G16:G17) | M15: =IF(H15<0,"Section 1.1 - Number of outstanding requests from previous reporting periods cannot be negative","")
A16: • Outstanding from previous reporting period | G16: 0 | M16: =IF(H16<0,"Section 1.1 - Number of ""Outstanding requests from previous reporting periods"" cannot be negative","")
A17: • Outstanding from more than one reporting period | G17: 0 | M17: =IF(H17<0,"Section 1.1 - Number of outstanding requests from the previous reporting period cannot be negative","")
A18: Total | H18: =SUM(H14:J15) | M18: =IF(H18<0,"Section 1.1 - Number of requests cannot be negative","")
A19: Closed during reporting period | H19: 0 | M19: =IF(H19<0,"Section 1.1 - Number of requests closed during the reporting period cannot be negative","")
A20: Carried over to next reporting period | H20: =G21+G22 | M20: =IF(H20<>(H18-H19),"Section 1.1 - The ""Carried over to next reporting period"" must equal to the ""Total"" minus ""Closed during reporting period"" of Section 1.1","")
A21: • Carried over within legislated timeline | G21: 0
A22: • Carried over beyond legislated timeline | G22: 0
A24: 1.2 Sources of requests
A26: Source | G26: Number of Requests
A27: Media | G27: 0
A28: Academia | G28: 0
A29: Business (private sector) | G29: 0
A30: Organization | G30: 0
A31: Public | G31: 0
A32: Decline to Identify | G32: 0
A33: Total | G33: =SUM(G27:J32) | M33: =IF(H14<>G33,"Section 1.2 - The ""Total"" must be equal to ""Received during reporting period"" of Section 1.1","")
A35: 1.3 Channels of requests
A37: Source | G37: Number of Requests
A38: Online | G38: 0
A39: E-mail | G39: 0
A40: Mail | G40: 0
A41: In person | G41: 0
A42: Phone | G42: 0
A43: Fax | G43: 0
A44: Total | G44: =SUM(G38:J43) | M44: =IF(H14<>G44,"Section 1.3 - The ""Total"" must be equal to ""Received during reporting period"" of Section 1.1","")
A46: Section 2: Informal Requests
A48: 2.1 Number of informal requests
H49: Number of Requests
A50: Received during reporting period | H50: 0
A51: Outstanding from previous reporting periods | H51: =SUM(G52:G53)
A52: • Outstanding from previous reporting period | G52: 0
...

Sheet Priv
A4: Statistical Report on the Privacy Act
E6: Name of institution: | H6: Treasury Board of Canada Secretariat | O6: You must enter an institution's name
E8: Reporting period: | H8: 44287 | K8: to | L8: 44651
A10: Section 1: Requests Under the Privacy Act
A12: 1.1 Number of requests received
H14: Number of Requests
A15: Received during reporting period | H15: 84
A16: Outstanding from previous reporting periods | H16: =SUM(G17:G18)
A17: • Outstanding from previous reporting period | G17: 4
A18: • Outstanding from more than one reporting period | G18: 2
A19: Total | H19: =SUM(H15:J16)
A20: Closed during reporting period | H20: 78
A21: Carried over to next reporting period | H21: =SUM(G22:G23) | K21: =IF(H21<>(H19-H20),"Section 1.1 - ""Carried over to the next period"" should be equal to the sum of ""Carried over within legislated timeline"" and ""Carried over beyond legislated timeline""","")
A22: • Carried over within legislated timeline | G22: 9 | K22: =IF(H21<>(H19-H20),"Section 1.1 - The ""Carried over to next reporting period"" must be equal to the ""Total"" minus ""Closed during the reporting period""","")
A23: • Carried over beyond legislated timeline | G23: 3 | K23: =IF(H23<0,"Section 1.1 - Carried over to next reporting period cannot be negative","")
A25: 1.2 Channels of requests
A27: Source | G27: Number of Requests
A28: Online | G28: 60
A29: E-mail | G29: 23
A30: Mail | G30: 1
A31: In person | G31: 0
A32: Phone | G32: 0
A33: Fax | G33: 0
A34: Total | G34: =SUM(G28:J33) | K34: =IF(G34<>H15,"Section 1.2 - The ""Total"" must be equal to ""Received during reporting period"" of Section 1.1","")
A36: Section 2: Informal requests
A40: 2.1 Number of informal requests
H41: Number of Requests
A42: Received during reporting period | H42: 0
A43: Outstanding from previous reporting periods | H43: =SUM(G44:G45)
A44: • Outstanding from previous reporting period | G44: 0
A45: • Outstanding from more than one reporting period | G45: 0
A46: Total | H46: =SUM(H42:J43)
A47: Closed during reporting period | H47: 0
A48: Carried over to next reporting period | H48: =H46-H47
A50: 2.2 Channels of informal requests
A52: Source | G52: Number of Requests
A53: Online | G53: 0
A54: E-mail | G54: 0
A55: Mail | G55: 0
A56: In person | G56: 0
...

Sheet ATI_ForConsumption
A1: Inst | B1: =ATI!D6
A2: Report | B2: 2021;2022
A3: Q1R1C1 | B3: =ATI!H14 | C3: 1,1
A4: Q1R2C1 | B4: =ATI!H15 | C4: 1,1
A5: Q1R3C1 | B5: =ATI!G16 | C5: 1,1
A6: Q1R4C1 | B6: =ATI!G17 | C6: 1,1
A7: Q1R5C1 | B7: =ATI!H18 | C7: 1,1
A8: Q1R6C1 | B8: =ATI!H19 | C8: 1,1
A9: Q1R7C1 | B9: =ATI!H20 | C9: 1,1
A10: Q1R8C1 | B10: =ATI!G21 | C10: 1,1
A11: Q1R9C1 | B11: =ATI!G22 | C11: 1,1
A12: Q2R1C1 | B12: =ATI!G27 | C12: 1,2
A13: Q2R2C1 | B13: =ATI!G28 | C13: 1,2
A14: Q2R3C1 | B14: =ATI!G29 | C14: 1,2
A15: Q2R4C1 | B15: =ATI!G30 | C15: 1,2
A16: Q2R5C1 | B16: =ATI!G31 | C16: 1,2
A17: Q2R6C1 | B17: =ATI!G32 | C17: 1,2
A18: Q2R7C1 | B18: =ATI!G33 | C18: 1,2
A19: Q3R1C1 | B19: =ATI!G38 | C19: 1,3
A20: Q3R2C1 | B20: =ATI!G39 | C20: 1,3
A21: Q3R3C1 | B21: =ATI!G40 | C21: 1,3
A22: Q3R4C1 | B22: =ATI!G41 | C22: 1,3
A23: Q3R5C1 | B23: =ATI!G42 | C23: 1,3
A24: Q3R6C1 | B24: =ATI!G43 | C24: 1,3
A25: Q3R7C1 | B25: =ATI!G44 | C25: 1,3
A26: Q4R1C1 | B26: =ATI!H50 | C26: 2,1
A27: Q4R2C1 | B27: =ATI!H51 | C27: 2,1
A28: Q4R3C1 | B28: =ATI!G52 | C28: 2,1
A29: Q4R4C1 | B29: =ATI!G53 | C29: 2,1
A30: Q4R5C1 | B30: =ATI!H54 | C30: 2,1
A31: Q4R6C1 | B31: =ATI!H55 | C31: 2,1
A32: Q4R7C1 | B32: =ATI!H56 | C32: 2,1
A33: Q5R1C1 | B33: =ATI!G61 | C33: 2,2
A34: Q5R2C1 | B34: =ATI!G62 | C34: 2,2
A35: Q5R3C1 | B35: =ATI!G63 | C35: 2,2
A36: Q5R4C1 | B36: =ATI!G64 | C36: 2,2
A37: Q5R5C1 | B37: =ATI!G65 | C37: 2,2
A38: Q5R6C1 | B38: =ATI!G66 | C38: 2,2
A39: Q5R7C1 | B39: =ATI!G67 | C39: 2,2
A40: Q6R1C1 | B40: =ATI!A73 | C40: 2,3
...

Sheet Privacy_ForConsumption
A1: Inst | B1: =Priv!H6
A2: Report | B2: 2021;2022
A3: Q1R1C1 | B3: =Priv!H15 | C3: 1,1
A4: Q1R2C1 | B4: =Priv!H16 | C4: 1,1
A5: Q1R3C1 | B5: =Priv!G17 | C5: 1,1
A6: Q1R4C1 | B6: =Priv!G18 | C6: 1,1
A7: Q1R5C1 | B7: =Priv!H19 | C7: 1,1
A8: Q1R6C1 | B8: =Priv!H20 | C8: 1,1
A9: Q1R7C1 | B9: =Priv!H21 | C9: 1,1
A10: Q1R8C1 | B10: =Priv!G22 | C10: 1,1
A11: Q1R9C1 | B11: =Priv!G23 | C11: 1,1
A12: Q2R1C1 | B12: =Priv!G28 | C12: 1,2
A13: Q2R2C1 | B13: =Priv!G29 | C13: 1,2
A14: Q2R3C1 | B14: =Priv!G30 | C14: 1,2
A15: Q2R4C1 | B15: =Priv!G31 | C15: 1,2
A16: Q2R5C1 | B16: =Priv!G32 | C16: 1,2
A17: Q2R6C1 | B17: =Priv!G33 | C17: 1,2
A18: Q2R7C1 | B18: =Priv!G34 | C18: 1,2
A19: Q3R1C1 | B19: =Priv!H42 | C19: 2,1
A20: Q3R2C1 | B20: =Priv!H43 | C20: 2,1
A21: Q3R3C1 | B21: =Priv!G44 | C21: 2,1
A22: Q3R4C1 | B22: =Priv!G45 | C22: 2,1
A23: Q3R5C1 | B23: =Priv!H46 | C23: 2,1
A24: Q3R6C1 | B24: =Priv!H47 | C24: 2,1
A25: Q3R7C1 | B25: =Priv!H48 | C25: 2,1
A26: Q4R1C1 | B26: =Priv!G53 | C26: 2,2
A27: Q4R2C1 | B27: =Priv!G54 | C27: 2,2
A28: Q4R3C1 | B28: =Priv!G55 | C28: 2,2
A29: Q4R4C1 | B29: =Priv!G56 | C29: 2,2
A30: Q4R5C1 | B30: =Priv!G57 | C30: 2,2
A31: Q4R6C1 | B31: =Priv!G58 | C31: 2,2
A32: Q4R7C1 | B32: =Priv!G59 | C32: 2,2
A33: Q5R1C1 | B33: =Priv!A65 | C33: 2,3
A34: Q5R1C2 | B34: =Priv!B65 | C34: 2,3
A35: Q5R1C3 | B35: =Priv!C65 | C35: 2,3
A36: Q5R1C4 | B36: =Priv!D65 | C36: 2,3
A37: Q5R1C5 | B37: =Priv!E65 | C37: 2,3
A38: Q5R1C6 | B38: =Priv!F65 | C38: 2,3
A39: Q5R1C7 | B39: =Priv!G65 | C39: 2,3
A40: Q6R1C1 | B40: =Priv!A71 | C40: 2,4
...
