Workbook

Sheet Supplemental Report 2024-25
A4: Supplemental Statistical Report on the Access to Information Act and the Privacy Act
A7: Name of institution: | D7: National Defence | K7: You must enter an institution's name
A9: Reporting period: | D9: 45017 | G9: to | H9: 45382
A11: Section 1: Requests Carried Over and Active Complaints Under the Access to Information Act
A13: 1.1 Requests carried over to next reporting period, broken down by reporting period received
A15: Reporting Period Requests Carried Over Were Received | D15: Requests Carried Over that are Within Legislated Timelines as of March 31, 2025 | F15: Requests Carried Over that are Beyond Legislated Timelines as of March 31, 2025 | H15: Total
A17: Received in 2024-25 | D17: 0 | F17: 0 | H17: =SUM(D17:G18)
A19: Received in 2023-24 | D19: 0 | F19: 186 | H19: =SUM(D19:G20)
A21: Received in 2022-23 | D21: 1852 | F21: 2038 | H21: =SUM(D21:G22)
A23: Received in 2021-22 | D23: 177 | F23: 761 | H23: =SUM(D23:G24)
A25: Received in 2020-21 | D25: 938 | F25: 3 | H25: =SUM(D25:G26)
A27: Received in 2019-20 | D27: 401 | F27: 404 | H27: =SUM(D27:G28)
A29: Received in 2018-19 | D29: 3 | F29: 300 | H29: =SUM(D29:G30)
A31: Received in 2017-18 | D31: 303 | F31: 2 | H31: =SUM(D31:G32)
A33: Received in 2016-17 | D33: 164 | F33: 166 | H33: =SUM(D33:G34)
A35: Received in 2015-16 or earlier | D35: 1 | F35: 147 | H35: =SUM(D35:G36)
A37: Total | D37: =SUM(D17:E36) | F37: =SUM(F17:G36) | H37: =SUM(D37:G38) | J37: Row 11, Col. 3 of Section 1.1 must equal Row 7, Col. 1 of Section 1.1 of the 2024-25 Statistical Report on the Access to Information Act
A40: 1.2 Active complaints with the Information Commissioner of Canada, broken down by reporting period received
A43: Reporting Period Active Complaints Were Received by Institution | D43: Number of Active Complaints
A45: Received in 2024-25 | D45: 2
A47: Received in 2023-24 | D47: 98
A49: Received in 2022-23 | D49: 80
A51: Received in 2021-22 | D51: 8
A53: Received in 2020-21 | D53: 0
A55: Received in 2019-20 | D55: 4
A57: Received in 2018-19 | D57: 3
A59: Received in 2017-18 | D59: 1
A61: Received in 2016-17 | D61: 0
A63: Received in 2015-16 or earlier | D63: 0
A65: Total | D65: =SUM(D45:E64)
A68: Section 2: Requests Carried Over and Active Complaints Under the Privacy Act
A70: 2.1 Requests carried over to next reporting period, broken down by reporting period received
A72: Reporting Period Requests Carried Over Were Received | D72: Requests Carried Over that are Within Legislated Timelines as of March 31, 2025 | F72: Requests Carried Over that are Beyond Legislated Timelines as of March 31, 2025 | H72: Total
A74: Received in 2024-25 | D74: 0 | F74: 0 | H74: =SUM(D74:G75)
A76: Received in 2023-24 | D76: 0 | F76: 524 | H76: =SUM(D76:G77)
A78: Received in 2022-23 | D78: 921 | F78: 1445 | H78: =SUM(D78:G79)
A80: Received in 2021-22 | D80: 523 | F80: 872 | H80: =SUM(D80:G81)
A82: Received in 2020-21 | D82: 1395 | F82: 1 | H82: =SUM(D82:G83)
A84: Received in 2019-20 | D84: 49 | F84: 50 | H84: =SUM(D84:G85)
A86: Received in 2018-19 | D86: 0 | F86: 0 | H86: =SUM(D86:G87)
...

Sheet ATIP_ForConsumption
A1: Inst | B1: ='Supplemental Report 2024-25'!D7
A2: Report | B2: 2023;2024
A3: Q1R1C1 | B3: ='Supplemental Report 2024-25'!D17 | C3: 1.1
A4: Q1R1C2 | B4: ='Supplemental Report 2024-25'!F17 | C4: 1.1
A5: Q1R2C1 | B5: ='Supplemental Report 2024-25'!D19 | C5: 1.1
A6: Q1R2C2 | B6: ='Supplemental Report 2024-25'!F19 | C6: 1.1
A7: Q1R3C1 | B7: ='Supplemental Report 2024-25'!D21 | C7: 1.1
A8: Q1R3C2 | B8: ='Supplemental Report 2024-25'!F21 | C8: 1.1
A9: Q1R4C1 | B9: ='Supplemental Report 2024-25'!D23 | C9: 1.1
A10: Q1R4C2 | B10: ='Supplemental Report 2024-25'!F23 | C10: 1.1
A11: Q1R5C1 | B11: ='Supplemental Report 2024-25'!D25 | C11: 1.1
A12: Q1R5C2 | B12: ='Supplemental Report 2024-25'!F25 | C12: 1.1
A13: Q1R6C1 | B13: ='Supplemental Report 2024-25'!D27 | C13: 1.1
A14: Q1R6C2 | B14: ='Supplemental Report 2024-25'!F27 | C14: 1.1
A15: Q1R7C1 | B15: ='Supplemental Report 2024-25'!D29 | C15: 1.1
A16: Q1R7C2 | B16: ='Supplemental Report 2024-25'!F29 | C16: 1.1
A17: Q1R8C1 | B17: ='Supplemental Report 2024-25'!D31 | C17: 1.1
A18: Q1R8C2 | B18: ='Supplemental Report 2024-25'!F31 | C18: 1.1
A19: Q1R9C1 | B19: ='Supplemental Report 2024-25'!D33 | C19: 1.1
A20: Q1R9C2 | B20: ='Supplemental Report 2024-25'!F33 | C20: 1.1
A21: Q1R10C1 | B21: ='Supplemental Report 2024-25'!D35 | C21: 1.1
A22: Q1R10C2 | B22: ='Supplemental Report 2024-25'!F35 | C22: 1.1
A23: Q2R1C1 | B23: ='Supplemental Report 2024-25'!D45 | C23: 1.2
A24: Q2R2C1 | B24: ='Supplemental Report 2024-25'!D47 | C24: 1.2
A25: Q2R3C1 | B25: ='Supplemental Report 2024-25'!D49 | C25: 1.2
A26: Q2R4C1 | B26: ='Supplemental Report 2024-25'!D51 | C26: 1.2
A27: Q2R5C1 | B27: ='Supplemental Report 2024-25'!D53 | C27: 1.2
A28: Q2R6C1 | B28: ='Supplemental Report 2024-25'!D55 | C28: 1.2
A29: Q2R7C1 | B29: ='Supplemental Report 2024-25'!D57 | C29: 1.2
A30: Q2R8C1 | B30: ='Supplemental Report 2024-25'!D59 | C30: 1.2
A31: Q2R9C1 | B31: ='Supplemental Report 2024-25'!D61 | C31: 1.2
A32: Q2R10C1 | B32: ='Supplemental Report 2024-25'!D63 | C32: 1.2
A33: Q3R1C1 | B33: ='Supplemental Report 2024-25'!D74 | C33: 2.1
A34: Q3R1C2 | B34: ='Supplemental Report 2024-25'!F74 | C34: 2.1
A35: Q3R2C1 | B35: ='Supplemental Report 2024-25'!D76 | C35: 2.1
A36: Q3R2C2 | B36: ='Supplemental Report 2024-25'!F76 | C36: 2.1
A37: Q3R3C1 | B37: ='Supplemental Report 2024-25'!D78 | C37: 2.1
A38: Q3R3C2 | B38: ='Supplemental Report 2024-25'!F78 | C38: 2.1
A39: Q3R4C1 | B39: ='Supplemental Report 2024-25'!D80 | C39: 2.1
A40: Q3R4C2 | B40: ='Supplemental Report 2024-25'!F80 | C40: 2.1
...
