Workbook

Sheet Rapport supplémentaire 2024-25
A4: Rapport statistique supplémentaire sur la Loi sur l'accès à l'information et la Loi sur la protection des renseignements personnels
A7: Nom de l'institution : | D7: Secrétariat du Conseil du Trésor du Canada | L7: Vous devez entrer le nom d'une institution.
A9: Période d'établissement de rapport : | D9: 45383 | G9: au | H9: 45747
A11: Section 1 : Demandes reportées et plaintes actives en vertu de la Loi sur l'accès à l'information
A13: 1.1 Demandes reportées à la prochaine période d'établissement de rapports, ventilées par période d'établissement de rapports reçue
A15: Période d'établissement de rapports au cours de laquelle les demandes reportées ont été reçues | D15: Demandes reportées dans les délais prescrits par la Loi en date du 31 mars 2025 | F15: Demandes reportées dépassant les délais prescrits par la Loi en date du 31 mars 2025 | H15: Total
A17: Reçues en 2024-2025 | D17: 0 | F17: 0 | H17: =SUM(D17:G18)
A19: Reçues en 2023-2024 | D19: 0 | F19: 58 | H19: =SUM(D19:G20)
A21: Reçues en 2022-2023 | D21: 136 | F21: 194 | H21: =SUM(D21:G22)
A23: Reçues en 2021-2022 | D23: 51 | F23: 54 | H23: =SUM(D23:G24)
A25: Reçues en 2020-2021 | D25: 105 | F25: 3 | H25: =SUM(D25:G26)
A27: Reçues en 2019-2020 | D27: 31 | F27: 34 | H27: =SUM(D27:G28)
A29: Reçues en 2018-2019 | D29: 2 | F29: 11 | H29: =SUM(D29:G30)
A31: Reçues en 2017-2018 | D31: 13 | F31: 0 | H31: =SUM(D31:G32)
A33: Reçues en 2016-2017 | D33: 18 | F33: 18 | H33: =SUM(D33:G34)
A35: Reçues en 2015-2016 ou plus tôt | D35: 1 | F35: 7 | H35: =SUM(D35:G36)
A37: Total | D37: =SUM(D17:E36) | F37: =SUM(F17:G36) | H37: =SUM(D37:G38) | J37: Rangée 11, col. 3 de la section 1.1 doit être égale à la rangée 7, col. 1 de la section 1.1 du Rapport statistique sur la Loi sur l’accès à l’information 2024-2025
A40: 1.2 Plaintes actives auprès du Commissaire à l'information du Canada, ventilées par période d'établissement de rapports reçue
A43: Période d'établissement de rapports au cours de laquelle les plaintes actives ont été reçues par l'institution | D43: Nombre de plaintes actives
A45: Reçues en 2024-2025 | D45: 0
A47: Reçues en 2023-2024 | D47: 21
A49: Reçues en 2022-2023 | D49: 13
A51: Reçues en 2021-2022 | D51: 3
A53: Reçues en 2020-2021 | D53: 5
A55: Reçues en 2019-2020 | D55: 0
A57: Reçues en 2018-2019 | D57: 0
A59: Reçues en 2017-2018 | D59: 0
A61: Reçues en 2016-2017 | D61: 0
A63: Reçues en 2015-2016 ou plus tôt | D63: 0
A65: Total | D65: =SUM(D45:E64)
A68: Section 2 : Demandes reportées et plaintes actives en vertu de la Loi sur la protection des renseignements personnels
A70: 2.1 Demandes reportées à la prochaine période d'établissement de rapports, ventilées par période d'établissement de rapports reçue
A72: Période d'établissement de rapports au cours de laquelle les demandes reportées ont été reçues | D72: Demandes reportées dans les délais prescrits par la Loi en date du 31 mars 2025 | F72: Demandes reportées dépassant les délais prescrits par la Loi en date du 31 mars 2025 | H72: Total
A74: Reçues en 2024-2025 | D74: 0 | F74: 0 | H74: =SUM(D74:G75)
A76: Reçues en 2023-2024 | D76: 0 | F76: 17 | H76: =SUM(D76:G77)
A78: Reçues en 2022-2023 | D78: 17 | F78: 34 | H78: =SUM(D78:G79)
A80: Reçues en 2021-2022 | D80: 17 | F80: 9 | H80: =SUM(D80:G81)
A82: Reçues en 2020-2021 | D82: 26 | F82: 0 | H82: =SUM(D82:G83)
A84: Reçues en 2019-2020 | D84: 7 | F84: 7 | H84: =SUM(D84:G85)
A86: Reçues en 2018-2019 | D86: 0 | F86: 1 | H86: =SUM(D86:G87)
...

Sheet ATIP_ForConsumption
A1: Inst | B1: ='Rapport supplémentaire 2024-25'!D7
A2: Report | B2: 2023;2024
A3: Q1R1C1 | B3: ='Rapport supplémentaire 2024-25'!D17 | C3: 1.1
A4: Q1R1C2 | B4: ='Rapport supplémentaire 2024-25'!F17 | C4: 1.1
A5: Q1R2C1 | B5: ='Rapport supplémentaire 2024-25'!D19 | C5: 1.1
A6: Q1R2C2 | B6: ='Rapport supplémentaire 2024-25'!F19 | C6: 1.1
A7: Q1R3C1 | B7: ='Rapport supplémentaire 2024-25'!D21 | C7: 1.1
A8: Q1R3C2 | B8: ='Rapport supplémentaire 2024-25'!F21 | C8: 1.1
A9: Q1R4C1 | B9: ='Rapport supplémentaire 2024-25'!D23 | C9: 1.1
A10: Q1R4C2 | B10: ='Rapport supplémentaire 2024-25'!F23 | C10: 1.1
A11: Q1R5C1 | B11: ='Rapport supplémentaire 2024-25'!D25 | C11: 1.1
A12: Q1R5C2 | B12: ='Rapport supplémentaire 2024-25'!F25 | C12: 1.1
A13: Q1R6C1 | B13: ='Rapport supplémentaire 2024-25'!D27 | C13: 1.1
A14: Q1R6C2 | B14: ='Rapport supplémentaire 2024-25'!F27 | C14: 1.1
A15: Q1R7C1 | B15: ='Rapport supplémentaire 2024-25'!D29 | C15: 1.1
A16: Q1R7C2 | B16: ='Rapport supplémentaire 2024-25'!F29 | C16: 1.1
A17: Q1R8C1 | B17: ='Rapport supplémentaire 2024-25'!D31 | C17: 1.1
A18: Q1R8C2 | B18: ='Rapport supplémentaire 2024-25'!F31 | C18: 1.1
A19: Q1R9C1 | B19: ='Rapport supplémentaire 2024-25'!D33 | C19: 1.1
A20: Q1R9C2 | B20: ='Rapport supplémentaire 2024-25'!F33 | C20: 1.1
A21: Q1R10C1 | B21: ='Rapport supplémentaire 2024-25'!D35 | C21: 1.1
A22: Q1R10C2 | B22: ='Rapport supplémentaire 2024-25'!F35 | C22: 1.1
A23: Q2R1C1 | B23: ='Rapport supplémentaire 2024-25'!D45 | C23: 1.2
A24: Q2R2C1 | B24: ='Rapport supplémentaire 2024-25'!D47 | C24: 1.2
A25: Q2R3C1 | B25: ='Rapport supplémentaire 2024-25'!D49 | C25: 1.2
A26: Q2R4C1 | B26: ='Rapport supplémentaire 2024-25'!D51 | C26: 1.2
A27: Q2R5C1 | B27: ='Rapport supplémentaire 2024-25'!D53 | C27: 1.2
A28: Q2R6C1 | B28: ='Rapport supplémentaire 2024-25'!D55 | C28: 1.2
A29: Q2R7C1 | B29: ='Rapport supplémentaire 2024-25'!D57 | C29: 1.2
A30: Q2R8C1 | B30: ='Rapport supplémentaire 2024-25'!D59 | C30: 1.2
A31: Q2R9C1 | B31: ='Rapport supplémentaire 2024-25'!D61 | C31: 1.2
A32: Q2R10C1 | B32: ='Rapport supplémentaire 2024-25'!D63 | C32: 1.2
A33: Q3R1C1 | B33: ='Rapport supplémentaire 2024-25'!D74 | C33: 2.1
A34: Q3R1C2 | B34: ='Rapport supplémentaire 2024-25'!F74 | C34: 2.1
A35: Q3R2C1 | B35: ='Rapport supplémentaire 2024-25'!D76 | C35: 2.1
A36: Q3R2C2 | B36: ='Rapport supplémentaire 2024-25'!F76 | C36: 2.1
A37: Q3R3C1 | B37: ='Rapport supplémentaire 2024-25'!D78 | C37: 2.1
A38: Q3R3C2 | B38: ='Rapport supplémentaire 2024-25'!F78 | C38: 2.1
A39: Q3R4C1 | B39: ='Rapport supplémentaire 2024-25'!D80 | C39: 2.1
A40: Q3R4C2 | B40: ='Rapport supplémentaire 2024-25'!F80 | C40: 2.1
...
